{"name": "Unsuccessful login with invalid credentials", "status": "broken", "statusDetails": {"message": "selenium.common.exceptions.SessionNotCreatedException: Message: session not created: This version of ChromeDriver only supports Chrome version 114\nCurrent browser version is 128.0.6613.119 with binary path /usr/bin/google-chrome\nStacktrace:\n#0 0x60bb86ba74e3 <unknown>\n#1 0x60bb868d6c76 <unknown>\n#2 0x60bb8690404a <unknown>\n#3 0x60bb868ff4a1 <unknown>\n#4 0x60bb868fc029 <unknown>\n#5 0x60bb8693accc <unknown>\n#6 0x60bb8693a47f <unknown>\n#7 0x60bb86931de3 <unknown>\n#8 0x60bb869072dd <unknown>\n#9 0x60bb8690834e <unknown>\n#10 0x60bb86b673e4 <unknown>\n#11 0x60bb86b6b3d7 <unknown>\n#12 0x60bb86b75b20 <unknown>\n#13 0x60bb86b6c023 <unknown>\n#14 0x60bb86b3a1aa <unknown>\n#15 0x60bb86b906b8 <unknown>\n#16 0x60bb86b90847 <unknown>\n#17 0x60bb86ba0243 <unknown>\n#18 0x75acaf894ac3 <unknown>\n\n", "trace": "  File \"/home/sujon/Desktop/DevOps_GO/.venv/lib/python3.10/site-packages/behave/model.py\", line 1329, in run\n    match.run(runner.context)\n  File \"/home/sujon/Desktop/DevOps_GO/.venv/lib/python3.10/site-packages/behave/matchers.py\", line 98, in run\n    self.func(context, *args, **kwargs)\n  File \"features/steps/login_steps.py\", line 7, in step_impl\n    context.driver = webdriver.Chrome()\n  File \"/home/sujon/Desktop/DevOps_GO/.venv/lib/python3.10/site-packages/selenium/webdriver/chrome/webdriver.py\", line 45, in __init__\n    super().__init__(\n  File \"/home/sujon/Desktop/DevOps_GO/.venv/lib/python3.10/site-packages/selenium/webdriver/chromium/webdriver.py\", line 66, in __init__\n    super().__init__(command_executor=executor, options=options)\n  File \"/home/sujon/Desktop/DevOps_GO/.venv/lib/python3.10/site-packages/selenium/webdriver/remote/webdriver.py\", line 212, in __init__\n    self.start_session(capabilities)\n  File \"/home/sujon/Desktop/DevOps_GO/.venv/lib/python3.10/site-packages/selenium/webdriver/remote/webdriver.py\", line 299, in start_session\n    response = self.execute(Command.NEW_SESSION, caps)[\"value\"]\n  File \"/home/sujon/Desktop/DevOps_GO/.venv/lib/python3.10/site-packages/selenium/webdriver/remote/webdriver.py\", line 354, in execute\n    self.error_handler.check_response(response)\n  File \"/home/sujon/Desktop/DevOps_GO/.venv/lib/python3.10/site-packages/selenium/webdriver/remote/errorhandler.py\", line 229, in check_response\n    raise exception_class(message, screen, stacktrace)\n"}, "steps": [{"name": "Given the user is on the login page", "status": "broken", "statusDetails": {"message": "selenium.common.exceptions.SessionNotCreatedException: Message: session not created: This version of ChromeDriver only supports Chrome version 114\nCurrent browser version is 128.0.6613.119 with binary path /usr/bin/google-chrome\nStacktrace:\n#0 0x60bb86ba74e3 <unknown>\n#1 0x60bb868d6c76 <unknown>\n#2 0x60bb8690404a <unknown>\n#3 0x60bb868ff4a1 <unknown>\n#4 0x60bb868fc029 <unknown>\n#5 0x60bb8693accc <unknown>\n#6 0x60bb8693a47f <unknown>\n#7 0x60bb86931de3 <unknown>\n#8 0x60bb869072dd <unknown>\n#9 0x60bb8690834e <unknown>\n#10 0x60bb86b673e4 <unknown>\n#11 0x60bb86b6b3d7 <unknown>\n#12 0x60bb86b75b20 <unknown>\n#13 0x60bb86b6c023 <unknown>\n#14 0x60bb86b3a1aa <unknown>\n#15 0x60bb86b906b8 <unknown>\n#16 0x60bb86b90847 <unknown>\n#17 0x60bb86ba0243 <unknown>\n#18 0x75acaf894ac3 <unknown>\n\n", "trace": "  File \"/home/sujon/Desktop/DevOps_GO/.venv/lib/python3.10/site-packages/behave/model.py\", line 1329, in run\n    match.run(runner.context)\n  File \"/home/sujon/Desktop/DevOps_GO/.venv/lib/python3.10/site-packages/behave/matchers.py\", line 98, in run\n    self.func(context, *args, **kwargs)\n  File \"features/steps/login_steps.py\", line 7, in step_impl\n    context.driver = webdriver.Chrome()\n  File \"/home/sujon/Desktop/DevOps_GO/.venv/lib/python3.10/site-packages/selenium/webdriver/chrome/webdriver.py\", line 45, in __init__\n    super().__init__(\n  File \"/home/sujon/Desktop/DevOps_GO/.venv/lib/python3.10/site-packages/selenium/webdriver/chromium/webdriver.py\", line 66, in __init__\n    super().__init__(command_executor=executor, options=options)\n  File \"/home/sujon/Desktop/DevOps_GO/.venv/lib/python3.10/site-packages/selenium/webdriver/remote/webdriver.py\", line 212, in __init__\n    self.start_session(capabilities)\n  File \"/home/sujon/Desktop/DevOps_GO/.venv/lib/python3.10/site-packages/selenium/webdriver/remote/webdriver.py\", line 299, in start_session\n    response = self.execute(Command.NEW_SESSION, caps)[\"value\"]\n  File \"/home/sujon/Desktop/DevOps_GO/.venv/lib/python3.10/site-packages/selenium/webdriver/remote/webdriver.py\", line 354, in execute\n    self.error_handler.check_response(response)\n  File \"/home/sujon/Desktop/DevOps_GO/.venv/lib/python3.10/site-packages/selenium/webdriver/remote/errorhandler.py\", line 229, in check_response\n    raise exception_class(message, screen, stacktrace)\n"}, "start": 1725871437074, "stop": 1725871437985}, {"name": "When the user enters invalid credentials", "status": "skipped", "start": 1725871437986, "stop": 1725871437986}, {"name": "Then an error message should be displayed", "status": "skipped", "start": 1725871437986, "stop": 1725871437986}], "start": 1725871437072, "stop": 1725871437986, "uuid": "f1f40d02-1de0-4fdc-a8a3-000920b5e564", "historyId": "0534ab1fb4f268889b47866dd243051b", "fullName": "Login functionality: Unsuccessful login with invalid credentials", "labels": [{"name": "severity", "value": "normal"}, {"name": "feature", "value": "Login functionality"}, {"name": "framework", "value": "behave"}, {"name": "language", "value": "cpython3"}]}